Workbook

Sheet Information

Sheet SensorData
A1: SensorID | B1: LocationIdentifier | C1: Label | D1: Parameter | E1: ParameterUnit | F1: Type of measurement | G1: GapTolerance | H1: Instrument | I1: DataOwner | J1: Hilfsspalte | K1: TimeSeriesUniqueID | L1: UTC
A2: 10000 | B2: Ecosense_Meteo_Parking | C2: +170cm | D2: BatteryVoltage | E2: =IF(ISBLANK(D2),"-",VLOOKUP(D2,Parameter!$B$5:$D$160,3,FALSE)) -> V | F2: Min | G2: =IF(ISBLANK(B2),"-","PT60M") -> PT60M | H2: CR1000 | I2: AndreasChristen_A4 | J2: =B2&C2&D2 -> Ecosense_Meteo_Parking+170cmBatteryVoltage | K2: =VLOOKUP(J2,[1]TimeSeriesIDs!$A:$E,5,FALSE) -> b57ff40172524a6992efb8704f305613 | L2: 1
A3: 10001 | B3: Ecosense_Meteo_Parking | C3: +200cm | D3: AirTemp | E3: =IF(ISBLANK(D3),"-",VLOOKUP(D3,Parameter!$B$5:$D$160,3,FALSE)) -> degC | F3: Selected Value | G3: =IF(ISBLANK(B3),"-","PT60M") -> PT60M | H3: HygroVUE5 | I3: AndreasChristen_A4 | J3: =B3&C3&D3 -> Ecosense_Meteo_Parking+200cmAirTemp | K3: =VLOOKUP(J3,[1]TimeSeriesIDs!$A:$E,5,FALSE) -> 6619fb72da304df089e7d81488891097 | L3: 1
A4: 10001 | B4: Ecosense_Meteo_Parking | C4: +200cm | D4: RelHumidity | E4: =IF(ISBLANK(D4),"-",VLOOKUP(D4,Parameter!$B$5:$D$160,3,FALSE)) -> % | F4: Selected Value | G4: =IF(ISBLANK(B4),"-","PT60M") -> PT60M | H4: HygroVUE5 | I4: AndreasChristen_A4 | J4: =B4&C4&D4 -> Ecosense_Meteo_Parking+200cmRelHumidity | K4: =VLOOKUP(J4,[1]TimeSeriesIDs!$A:$E,5,FALSE) -> 67c68aba126d49c58f5bcbe734b32d34 | L4: 1
A5: 10002 | B5: Ecosense_Meteo_Parking | C5: +150cm | D5: LongwaveNetRad | E5: =IF(ISBLANK(D5),"-",VLOOKUP(D5,Parameter!$B$5:$D$160,3,FALSE)) -> W/m^2 | F5: Selected Value | G5: =IF(ISBLANK(B5),"-","PT60M") -> PT60M | H5: CNR4 | I5: AndreasChristen_A4 | J5: =B5&C5&D5 -> Ecosense_Meteo_Parking+150cmLongwaveNetRad | K5: =VLOOKUP(J5,[1]TimeSeriesIDs!$A:$E,5,FALSE) -> 04f226f7c9e34c87bf6ae02162b73118 | L5: 1
A6: 10002 | B6: Ecosense_Meteo_Parking | C6: +150cm | D6: NetRad | E6: =IF(ISBLANK(D6),"-",VLOOKUP(D6,Parameter!$B$5:$D$160,3,FALSE)) -> W/m^2 | F6: Selected Value | G6: =IF(ISBLANK(B6),"-","PT60M") -> PT60M | H6: CNR4 | I6: AndreasChristen_A4 | J6: =B6&C6&D6 -> Ecosense_Meteo_Parking+150cmNetRad | K6: =VLOOKUP(J6,[1]TimeSeriesIDs!$A:$E,5,FALSE) -> 510cd6c1fee4441098da0c3802262753 | L6: 1
A7: 10002 | B7: Ecosense_Meteo_Parking | C7: +150cm | D7: ShortwaveRad | E7: =IF(ISBLANK(D7),"-",VLOOKUP(D7,Parameter!$B$5:$D$160,3,FALSE)) -> W/m^2 | F7: Selected Value | G7: =IF(ISBLANK(B7),"-","PT60M") -> PT60M | H7: CNR4 | I7: AndreasChristen_A4 | J7: =B7&C7&D7 -> Ecosense_Meteo_Parking+150cmShortwaveRad | K7: =VLOOKUP(J7,[1]TimeSeriesIDs!$A:$E,5,FALSE) -> 5e28da786fe44dab99294e12d5041a55 | L7: 1
A8: 10002 | B8: Ecosense_Meteo_Parking | C8: +150cm | D8: RefShortwaveRad | E8: =IF(ISBLANK(D8),"-",VLOOKUP(D8,Parameter!$B$5:$D$160,3,FALSE)) -> W/m^2 | F8: Selected Value | G8: =IF(ISBLANK(B8),"-","PT60M") -> PT60M | H8: CNR4 | I8: AndreasChristen_A4 | J8: =B8&C8&D8 -> Ecosense_Meteo_Parking+150cmRefShortwaveRad | K8: =VLOOKUP(J8,[1]TimeSeriesIDs!$A:$E,5,FALSE) -> 76e84e4b1e614cd8b76a6233fe73fe00 | L8: 1
A9: 10002 | B9: Ecosense_Meteo_Parking | C9: +150cm | D9: RefLongwaveRad | E9: =IF(ISBLANK(D9),"-",VLOOKUP(D9,Parameter!$B$5:$D$160,3,FALSE)) -> W/m^2 | F9: Selected Value | G9: =IF(ISBLANK(B9),"-","PT60M") -> PT60M | H9: CNR4 | I9: AndreasChristen_A4 | J9: =B9&C9&D9 -> Ecosense_Meteo_Parking+150cmRefLongwaveRad | K9: =VLOOKUP(J9,[1]TimeSeriesIDs!$A:$E,5,FALSE) -> 8062ac5049164776bef8d8afd914e30b | L9: 1
A10: 10002 | B10: Ecosense_Meteo_Parking | C10: +150cm | D10: Albedo | E10: =IF(ISBLANK(D10),"-",VLOOKUP(D10,Parameter!$B$5:$D$160,3,FALSE)) -> % | F10: Selected Value | G10: =IF(ISBLANK(B10),"-","PT60M") -> PT60M | H10: CNR4 | I10: AndreasChristen_A4 | J10: =B10&C10&D10 -> Ecosense_Meteo_Parking+150cmAlbedo | K10: =VLOOKUP(J10,[1]TimeSeriesIDs!$A:$E,5,FALSE) -> d97b8945ae9f453dad091b4a591b0ee2 | L10: 1
A11: 10002 | B11: Ecosense_Meteo_Parking | C11: +150cm | D11: LongwaveRad | E11: =IF(ISBLANK(D11),"-",VLOOKUP(D11,Parameter!$B$5:$D$160,3,FALSE)) -> W/m^2 | F11: Selected Value | G11: =IF(ISBLANK(B11),"-","PT60M") -> PT60M | H11: CNR4 | I11: AndreasChristen_A4 | J11: =B11&C11&D11 -> Ecosense_Meteo_Parking+150cmLongwaveRad | K11: =VLOOKUP(J11,[1]TimeSeriesIDs!$A:$E,5,FALSE) -> dd93db183e8a48098bb5f78567dc6a1d | L11: 1
A12: 10002 | B12: Ecosense_Meteo_Parking | C12: +150cm | D12: InternalTemp | E12: =IF(ISBLANK(D12),"-",VLOOKUP(D12,Parameter!$B$5:$D$160,3,FALSE)) -> degC | F12: Selected Value | G12: =IF(ISBLANK(B12),"-","PT60M") -> PT60M | H12: CNR4 | I12: AndreasChristen_A4 | J12: =B12&C12&D12 -> Ecosense_Meteo_Parking+150cmInternalTemp | K12: =VLOOKUP(J12,[1]TimeSeriesIDs!$A:$E,5,FALSE) -> e41a67651c844a099adc80e561891591 | L12: 1
A13: 10002 | B13: Ecosense_Meteo_Parking | C13: +150cm | D13: LongwaveRadTc | E13: =IF(ISBLANK(D13),"-",VLOOKUP(D13,Parameter!$B$5:$D$160,3,FALSE)) -> W/m^2 | F13: Selected Value | G13: =IF(ISBLANK(B13),"-","PT60M") -> PT60M | H13: CNR4 | I13: AndreasChristen_A4 | J13: =B13&C13&D13 -> Ecosense_Meteo_Parking+150cmLongwaveRadTc | K13: =VLOOKUP(J13,[1]TimeSeriesIDs!$A:$E,5,FALSE) -> e597dcfbb21c4ad69702514afe21375b | L13: 1
... A15: 10002 | B15: Ecosense_Meteo_Parking | C15: +150cm | D15: ShortwaveNetRad | E15: =IF(ISBLANK(D15),"-",VLOOKUP(D15,Parameter!$B$5:$D$160,3,FALSE)) -> W/m^2 | F15: Selected Value | G15: =IF(ISBLANK(B15),"-","PT60M") -> PT60M | H15: CNR4 | I15: AndreasChristen_A4 | J15: =B15&C15&D15 -> Ecosense_Meteo_Parking+150cmShortwaveNetRad | K15: =VLOOKUP(J15,[1]TimeSeriesIDs!$A:$E,5,FALSE) -> fe3a43f0958c4ca7af2fb2e8fd46e165 | L15: 1
A16: 10003 | B16: Ecosense_Meteo_Parking | C16: +300cm | D16: WindDiagnosticCode | E16: None | F16: Selected Value | G16: =IF(ISBLANK(B16),"-","PT60M") -> PT60M | H16: WindSonic | I16: AndreasChristen_A4 | J16: =B16&C16&D16 -> Ecosense_Meteo_Parking+300cmWindDiagnosticCode | K16: =VLOOKUP(J16,[1]TimeSeriesIDs!$A:$E,5,FALSE) -> 2c5677f79ad24ccfbaceebd540cc71b8 | L16: 1
A17: 10003 | B17: Ecosense_Meteo_Parking | C17: +300cm | D17: WindDir | E17: =IF(ISBLANK(D17),"-",VLOOKUP(D17,Parameter!$B$5:$D$160,3,FALSE)) -> deg | F17: Selected Value | G17: =IF(ISBLANK(B17),"-","PT60M") -> PT60M | H17: WindSonic | I17: AndreasChristen_A4 | J17: =B17&C17&D17 -> Ecosense_Meteo_Parking+300cmWindDir | K17: =VLOOKUP(J17,[1]TimeSeriesIDs!$A:$E,5,FALSE) -> 94b3d66bdc8b4e85ba6637c576755ee9 | L17: 1
A18: 10003 | B18: Ecosense_Meteo_Parking | C18: +300cm | D18: WindVel | E18: =IF(ISBLANK(D18),"-",VLOOKUP(D18,Parameter!$B$5:$D$160,3,FALSE)) -> m/s | F18: Selected Value | G18: =IF(ISBLANK(B18),"-","PT60M") -> PT60M | H18: WindSonic | I18: AndreasChristen_A4 | J18: =B18&C18&D18 -> Ecosense_Meteo_Parking+300cmWindVel | K18: =VLOOKUP(J18,[1]TimeSeriesIDs!$A:$E,5,FALSE) -> e4c77f99fe4b4544aa6b6338e6ea9018 | L18: 1
A19: 10004 | B19: Ecosense_Meteo_Parking | C19: +100cm | D19: PrecipIncrem | E19: =IF(ISBLANK(D19),"-",VLOOKUP(D19,Parameter!$B$5:$D$160,3,FALSE)) -> mm | F19: Sum | G19: =IF(ISBLANK(B19),"-","PT60M") -> PT60M | H19: TippingBucket | I19: AndreasChristen_A4 | J19: =B19&C19&D19 -> Ecosense_Meteo_Parking+100cmPrecipIncrem | K19: =VLOOKUP(J19,[1]TimeSeriesIDs!$A:$E,5,FALSE) -> bc2f8007500e421ab2e3574ee3fcdc40 | L19: 1
A20: 10005 | B20: Ecosense_MainTower | C20: ground | D20: SoilTemp | E20: degC | F20: Selected Value | G20: =IF(ISBLANK(B20),"-","PT60M") -> PT60M | H20: CS107 | I20: MarkusSulzer_A4 | J20: =B20&C20&D20 -> Ecosense_MainTowergroundSoilTemp | K20: =VLOOKUP(J20,[1]TimeSeriesIDs!$A:$E,5,FALSE) -> e8d883dad4224ddc906f40afb0a3a4af | L20: 0
A21: 10006 | B21: Ecosense_MainTower | C21: ground | D21: SoilHeatFlux | E21: W/m^2 | F21: Selected Value | G21: =IF(ISBLANK(B21),"-","PT60M") -> PT60M | H21: HFP01SC-L | I21: MarkusSulzer_A4 | J21: =B21&C21&D21 -> Ecosense_MainTowergroundSoilHeatFlux | K21: =VLOOKUP(J21,[1]TimeSeriesIDs!$A:$E,5,FALSE) -> 27d2bae26f5644bcaae47010c9a51836 | L21: 0
A22: 10006 | B22: Ecosense_MainTower | C22: ground | D22: SoilHeatFlux_Volt | E22: mV | F22: Selected Value | G22: =IF(ISBLANK(B22),"-","PT60M") -> PT60M | H22: HFP01SC-L | I22: MarkusSulzer_A4 | J22: =B22&C22&D22 -> Ecosense_MainTowergroundSoilHeatFlux_Volt | K22: =VLOOKUP(J22,[1]TimeSeriesIDs!$A:$E,5,FALSE) -> 4f1657b50f9b430682c6550a3390991f | L22: 0
A23: 10007 | B23: Ecosense_MainTower | C23: +2m | D23: AtmosPres | E23: kPa | F23: Selected Value | G23: =IF(ISBLANK(B23),"-","PT60M") -> PT60M | H23: BaroVUE10 | I23: MarkusSulzer_A4 | J23: =B23&C23&D23 -> Ecosense_MainTower+2mAtmosPres | K23: =VLOOKUP(J23,[1]TimeSeriesIDs!$A:$E,5,FALSE) -> 2e9aaade5d4b474f884c6c3804b29a50 | L23: 0
A24: 10007 | B24: Ecosense_MainTower | C24: +2m | D24: InternalTemp | E24: degC | F24: Selected Value | G24: =IF(ISBLANK(B24),"-","PT60M") -> PT60M | H24: BaroVUE10 | I24: MarkusSulzer_A4 | J24: =B24&C24&D24 -> Ecosense_MainTower+2mInternalTemp | K24: =VLOOKUP(J24,[1]TimeSeriesIDs!$A:$E,5,FALSE) -> 9985ab8834394bb8b5b608177ce364ad | L24: 0
A25: 10007 | B25: Ecosense_MainTower | C25: +2m | D25: Diagnosticcode | E25: None | F25: Selected Value | G25: =IF(ISBLANK(B25),"-","PT60M") -> PT60M | H25: BaroVUE10 | I25: MarkusSulzer_A4 | J25: =B25&C25&D25 -> Ecosense_MainTower+2mDiagnosticcode | K25: =VLOOKUP(J25,[1]TimeSeriesIDs!$A:$E,5,FALSE) -> fd89c530be354bcfabea41fd7c725b97 | L25: 0
A26: 10008 | B26: Ecosense_MainTower | C26: +47m | D26: WindDir_Volt | E26: mV | F26: Mean | G26: =IF(ISBLANK(B26),"-","PT60M") -> PT60M | H26: Young05103 | I26: MarkusSulzer_A4 | J26: =B26&C26&D26 -> Ecosense_MainTower+47mWindDir_Volt | K26: =VLOOKUP(J26,[1]TimeSeriesIDs!$A:$E,5,FALSE) -> 0c3bd96824c445bbabf8f0ebc43f0383 | L26: 0
A27: 10008 | B27: Ecosense_MainTower | C27: +47m | D27: WindGustVel | E27: m/s | F27: Max | G27: =IF(ISBLANK(B27),"-","PT60M") -> PT60M | H27: Young05103 | I27: MarkusSulzer_A4 | J27: =B27&C27&D27 -> Ecosense_MainTower+47mWindGustVel | K27: =VLOOKUP(J27,[1]TimeSeriesIDs!$A:$E,5,FALSE) -> 2f65d3ea10c4485291af951316860d6a | L27: 0
A28: 10008 | B28: Ecosense_MainTower | C28: +47m_from 21.06.2024 (sensor adjustment) | D28: WindDir | E28: deg | F28: Mean | G28: =IF(ISBLANK(B28),"-","PT60M") -> PT60M | H28: Young05103 | I28: MarkusSulzer_A4 | J28: =B28&C28&D28 -> Ecosense_MainTower+47m_from 21.06.2024 (sensor adjustment)WindDir | K28: =VLOOKUP(J28,[1]TimeSeriesIDs!$A:$E,5,FALSE) -> 4b8947eee2e94e40bbc8b3a2a1fef97e | L28: 0
A29: 10008 | B29: Ecosense_MainTower | C29: +47m | D29: Count | E29: None | F29: Sum | G29: =IF(ISBLANK(B29),"-","PT60M") -> PT60M | H29: Young52202 | I29: MarkusSulzer_A4 | J29: =B29&C29&D29 -> Ecosense_MainTower+47mCount | K29: =VLOOKUP(J29,[1]TimeSeriesIDs!$A:$E,5,FALSE) -> 529bef176f674e5bbf6ffab705b4af16 | L29: 0
A30: 10008 | B30: Ecosense_MainTower | C30: +47m | D30: WindVel | E30: m/s | F30: Mean | G30: =IF(ISBLANK(B30),"-","PT60M") -> PT60M | H30: Young05103 | I30: MarkusSulzer_A4 | J30: =B30&C30&D30 -> Ecosense_MainTower+47mWindVel | K30: =VLOOKUP(J30,[1]TimeSeriesIDs!$A:$E,5,FALSE) -> 8c45de0335b94199b3bd183deceea056 | L30: 0
A31: 10009 | B31: Ecosense_MainTower | C31: +2m | D31: VPDAVG | E31: hPa | F31: Mean | G31: =IF(ISBLANK(B31),"-","PT60M") -> PT60M | H31: HygroVUE10 | I31: MarkusSulzer_A4 | J31: =B31&C31&D31 -> Ecosense_MainTower+2mVPDAVG | K31: =VLOOKUP(J31,[1]TimeSeriesIDs!$A:$E,5,FALSE) -> 059cbc8fd49a48c09286168a25301b4e | L31: 0
... A213: 10039 | B213: Ecosense_MainTower | C213: +47m_SunTracker_direct | D213: ShortwaveRad_in | E213: W/m^2 | F213: Mean | G213: =IF(ISBLANK(B213),"-","PT60M") -> PT60M | H213: CHP 1 | I213: MarkusSulzer_A4 | J213: =B213&C213&D213 -> Ecosense_MainTower+47m_SunTracker_directShortwaveRad_in | K213: =VLOOKUP(J213,[1]TimeSeriesIDs!$A:$E,5,FALSE) -> 28022e50d0b24df1b6d351c5263b372e | L213: 0
A214: 10039 | B214: Ecosense_MainTower | C214: +47m_SunTracker | D214: InternalTemp | E214: =IF(ISBLANK(D214),"-",VLOOKUP(D214,[2]Parameter!$B$5:$D$160,3,FALSE)) -> degC | F214: Mean | G214: =IF(ISBLANK(B214),"-","PT60M") -> PT60M | H214: CHP 1 | I214: MarkusSulzer_A4 | J214: =B214&C214&D214 -> Ecosense_MainTower+47m_SunTrackerInternalTemp | K214: =VLOOKUP(J214,[1]TimeSeriesIDs!$A:$E,5,FALSE) -> 954eb229a0f44ecf881b67a8a95e4849 | L214: 0
A215: 10039 | B215: Ecosense_MainTower | C215: +47m_SunTracker_direct | D215: ShortwaveRad_in_Volt | E215: mV | F215: Mean | G215: =IF(ISBLANK(B215),"-","PT60M") -> PT60M | H215: CHP 1 | I215: MarkusSulzer_A4 | J215: =B215&C215&D215 -> Ecosense_MainTower+47m_SunTracker_directShortwaveRad_in_Volt | K215: =VLOOKUP(J215,[1]TimeSeriesIDs!$A:$E,5,FALSE) -> e17d55ddcdb547d78763bbc5fcd44d39 | L215: 0
A216: 10040 | B216: Ecosense_MainTower | C216: +47m_SunTracker_2 | D216: InternalTemp | E216: =IF(ISBLANK(D216),"-",VLOOKUP(D216,[2]Parameter!$B$5:$D$160,3,FALSE)) -> degC | F216: Mean | G216: =IF(ISBLANK(B216),"-","PT60M") -> PT60M | H216: CG 1 | I216: MarkusSulzer_A4 | J216: =B216&C216&D216 -> Ecosense_MainTower+47m_SunTracker_2InternalTemp | K216: =VLOOKUP(J216,[1]TimeSeriesIDs!$A:$E,5,FALSE) -> cac5b33c9bd94edfa5b860078f8e3d75 | L216: 0
A217: 10040 | B217: Ecosense_MainTower | C217: +47m_SunTracker_shaded | D217: LongwaveRad_in_Volt | E217: mV | F217: Mean | G217: =IF(ISBLANK(B217),"-","PT60M") -> PT60M | H217: CG 1 | I217: MarkusSulzer_A4 | J217: =B217&C217&D217 -> Ecosense_MainTower+47m_SunTracker_shadedLongwaveRad_in_Volt | K217: =VLOOKUP(J217,[1]TimeSeriesIDs!$A:$E,5,FALSE) -> d84cbd49d89a4ac1b6dfd9485078fc17 | L217: 0
A218: 10040 | B218: Ecosense_MainTower | C218: +47m_SunTracker_shaded | D218: LongwaveRad_in | E218: W/m^2 | F218: Mean | G218: =IF(ISBLANK(B218),"-","PT60M") -> PT60M | H218: CG 1 | I218: MarkusSulzer_A4 | J218: =B218&C218&D218 -> Ecosense_MainTower+47m_SunTracker_shadedLongwaveRad_in | K218: =VLOOKUP(J218,[1]TimeSeriesIDs!$A:$E,5,FALSE) -> fd1c2ad326ab44b4bb70066d15e1517e | L218: 0
A219: 10041 | B219: Ecosense_MainTower | C219: +27m | D219: PrecMovTot1hr | E219: mm/hr | F219: Sum | G219: =IF(ISBLANK(B219),"-","PT60M") -> PT60M | H219: Davis tippping bucket | I219: MarkusSulzer_A4 | J219: =B219&C219&D219 -> Ecosense_MainTower+27mPrecMovTot1hr | K219: =VLOOKUP(J219,[1]TimeSeriesIDs!$A:$E,5,FALSE) -> 6bbdef61207440afbc44dac3072edebb | L219: 0
A220: 10041 | B220: Ecosense_MainTower | C220: +27m | D220: PrecipIncrem | E220: mm | F220: Sum | G220: =IF(ISBLANK(B220),"-","PT60M") -> PT60M | H220: Davis tippping bucket | I220: MarkusSulzer_A4 | J220: =B220&C220&D220 -> Ecosense_MainTower+27mPrecipIncrem | K220: =VLOOKUP(J220,[1]TimeSeriesIDs!$A:$E,5,FALSE) -> e440d29a725c47a3b574fbb14a761afd | L220: 0
A221: 10042 | B221: Ecosense_MainTower | C221: Ceilometer_DetectionStatus | D221: Diagnosticcode | E221: None | F221: Selected Value | G221: =IF(ISBLANK(B221),"-","PT60M") -> PT60M | H221: CL31; 0=clear sky, 1=1 layer of clouds, 2=2 layers of clouds, 3=3 layers of clouds, 4=limited visibility due to fog, low clouds, or heavy rain | I221: MarkusSulzer_A4 | J221: =B221&C221&D221 -> Ecosense_MainTowerCeilometer_DetectionStatusDiagnosticcode | K221: =VLOOKUP(J221,[1]TimeSeriesIDs!$A:$E,5,FALSE) -> 82b9d0506e414c90b97ff87d40346522 | L221: 0
A222: 10042 | B222: Ecosense_MainTower | C222: Ceilometer_CloudBaseHeight_1 | D222: Distance | E222: m | F222: Selected Value | G222: =IF(ISBLANK(B222),"-","PT60M") -> PT60M | H222: CL31 | I222: MarkusSulzer_A4 | J222: =B222&C222&D222 -> Ecosense_MainTowerCeilometer_CloudBaseHeight_1Distance | K222: =VLOOKUP(J222,[1]TimeSeriesIDs!$A:$E,5,FALSE) -> ed29088fe84c4e5a9ef022536763f8af | L222: 0
...

Sheet deadSensors
A1: SensorID | B1: LocationIdentifier | C1: Label | D1: Parameter | E1: ParameterUnit | F1: Type of measurement | G1: GapTolerance | H1: Instrument | I1: DataOwner | J1: Hilfsspalte | K1: TimeSeriesUniqueID
A2: 10007 | B2: Ecosense_MainTower | C2: +2m | D2: AtmosPresSeaLevel | E2: hPa | F2: Selected Value | G2: =IF(ISBLANK(B2),"-","PT60M") -> PT60M | H2: BaroVUE10 | I2: MarkusSulzer_A4 | J2: =B2&C2&D2 -> Ecosense_MainTower+2mAtmosPresSeaLevel | K2: =VLOOKUP(J2,[1]TimeSeriesIDs!$A:$E,5,FALSE) -> 979d92deec364d988649e5b0495e16b9
A3: 30000 | B3: Ecosense_Experiment_Scaffold | C3: TM1_DD_2023_raw | D3: SoilMoisture | E3: m^3/m^3 | F3: Selected Value | G3: =IF(ISBLANK(B3),"-","PT60M") -> PT60M | H3: 5TM | I3: StefanieDumberger_A3_ClaraStock_B1 | J3: =B3&C3&D3 -> Ecosense_Experiment_ScaffoldTM1_DD_2023_rawSoilMoisture | K3: c627490362ba4234bf8b2ba65d43f115
A4: 30001 | B4: Ecosense_Experiment_Scaffold | C4: TM2_FF_2023_raw | D4: SoilMoisture | E4: m^3/m^3 | F4: Selected Value | G4: =IF(ISBLANK(B4),"-","PT60M") -> PT60M | H4: 5TM | I4: StefanieDumberger_A3_ClaraStock_B1 | J4: =B4&C4&D4 -> Ecosense_Experiment_ScaffoldTM2_FF_2023_rawSoilMoisture | K4: c4c91cc946ca4810a9aa7dce2e536a8e
A5: 30002 | B5: Ecosense_Experiment_Scaffold | C5: TM3_BF_2023_raw | D5: SoilMoisture | E5: m^3/m^3 | F5: Selected Value | G5: =IF(ISBLANK(B5),"-","PT60M") -> PT60M | H5: 5TM | I5: StefanieDumberger_A3_ClaraStock_B1 | J5: =B5&C5&D5 -> Ecosense_Experiment_ScaffoldTM3_BF_2023_rawSoilMoisture | K5: 7f980961d75147efa87df711f91d3b74
A6: 30003 | B6: Ecosense_Experiment_Scaffold | C6: TM4_DD_2023_raw | D6: SoilMoisture | E6: m^3/m^3 | F6: Selected Value | G6: =IF(ISBLANK(B6),"-","PT60M") -> PT60M | H6: 5TM | I6: StefanieDumberger_A3_ClaraStock_B1 | J6: =B6&C6&D6 -> Ecosense_Experiment_ScaffoldTM4_DD_2023_rawSoilMoisture | K6: fb4942bfb49f4609bbdb95887c4ce943
A7: 30004 | B7: Ecosense_Experiment_Scaffold | C7: TM5_BB_2023_raw | D7: SoilMoisture | E7: m^3/m^3 | F7: Selected Value | G7: =IF(ISBLANK(B7),"-","PT60M") -> PT60M | H7: 5TM | I7: StefanieDumberger_A3_ClaraStock_B1 | J7: =B7&C7&D7 -> Ecosense_Experiment_ScaffoldTM5_BB_2023_rawSoilMoisture | K7: bca2bfa1ec82453f832d7fbd35ad92cd
A8: 30005 | B8: Ecosense_Experiment_Scaffold | C8: TM6_FF_2023_raw | D8: SoilMoisture | E8: m^3/m^3 | F8: Selected Value | G8: =IF(ISBLANK(B8),"-","PT60M") -> PT60M | H8: 5TM | I8: StefanieDumberger_A3_ClaraStock_B1 | J8: =B8&C8&D8 -> Ecosense_Experiment_ScaffoldTM6_FF_2023_rawSoilMoisture | K8: a60bbfa83b094c7d8f93ec12dc26981d
A9: 30006 | B9: Ecosense_Experiment_Scaffold | C9: TM7_BF_2023_raw | D9: SoilMoisture | E9: m^3/m^3 | F9: Selected Value | G9: =IF(ISBLANK(B9),"-","PT60M") -> PT60M | H9: 5TM | I9: StefanieDumberger_A3_ClaraStock_B1 | J9: =B9&C9&D9 -> Ecosense_Experiment_ScaffoldTM7_BF_2023_rawSoilMoisture | K9: d4b5a2c6403149f293d8c9d04c52b4b4
A10: 30007 | B10: Ecosense_Experiment_Scaffold | C10: TM8_BB_2023_raw | D10: SoilMoisture | E10: m^3/m^3 | F10: Selected Value | G10: =IF(ISBLANK(B10),"-","PT60M") -> PT60M | H10: 5TM | I10: StefanieDumberger_A3_ClaraStock_B1 | J10: =B10&C10&D10 -> Ecosense_Experiment_ScaffoldTM8_BB_2023_rawSoilMoisture | K10: c44a11d468c34ae3bbdd6b41286f0059
A11: 30008 | B11: Ecosense_Experiment_Scaffold | C11: TM9_DD_2023_raw | D11: SoilMoisture | E11: m^3/m^3 | F11: Selected Value | G11: =IF(ISBLANK(B11),"-","PT60M") -> PT60M | H11: 5TM | I11: StefanieDumberger_A3_ClaraStock_B1 | J11: =B11&C11&D11 -> Ecosense_Experiment_ScaffoldTM9_DD_2023_rawSoilMoisture | K11: 1376c39cbee24a75ba3babea793749e0
A12: 30009 | B12: Ecosense_Experiment_Scaffold | C12: TM10_FF_2023_raw | D12: SoilMoisture | E12: m^3/m^3 | F12: Selected Value | G12: =IF(ISBLANK(B12),"-","PT60M") -> PT60M | H12: 5TM | I12: StefanieDumberger_A3_ClaraStock_B1 | J12: =B12&C12&D12 -> Ecosense_Experiment_ScaffoldTM10_FF_2023_rawSoilMoisture | K12: 43f4530303f34f82af379fffd9226426
A13: 30010 | B13: Ecosense_Experiment_Scaffold | C13: TM11_DD_2023_raw | D13: SoilMoisture | E13: m^3/m^3 | F13: Selected Value | G13: =IF(ISBLANK(B13),"-","PT60M") -> PT60M | H13: 5TM | I13: StefanieDumberger_A3_ClaraStock_B1 | J13: =B13&C13&D13 -> Ecosense_Experiment_ScaffoldTM11_DD_2023_rawSoilMoisture | K13: 63d56a8ade994cf288298a4df94dddec
A14: 30011 | B14: Ecosense_Experiment_Scaffold | C14: TM12_DD_2023_raw | D14: SoilMoisture | E14: m^3/m^3 | F14: Selected Value | G14: =IF(ISBLANK(B14),"-","PT60M") -> PT60M | H14: 5TM | I14: StefanieDumberger_A3_ClaraStock_B1 | J14: =B14&C14&D14 -> Ecosense_Experiment_ScaffoldTM12_DD_2023_rawSoilMoisture | K14: 11d20c76bb0947ceabae17272dafffb4
... A37: 30034 | B37: Ecosense_Experiment_Scaffold | C37: GS14_FF_2023_raw | D37: SoilMoisture | E37: m^3/m^3 | F37: Selected Value | G37: =IF(ISBLANK(B37),"-","PT60M") -> PT60M | H37: GS1 | I37: StefanieDumberger_A3_ClaraStock_B1 | J37: =B37&C37&D37 -> Ecosense_Experiment_ScaffoldGS14_FF_2023_rawSoilMoisture | K37: 03182e1be56e4e49b5005fa487984aec
A38: 30099 | B38: wurde fälschlicherweise vergeben, aber zeitnah korrigiert | G38: =IF(ISBLANK(B38),"-","PT60M") -> PT60M | J38: =B38&C38&D38 -> wurde fälschlicherweise vergeben, aber zeitnah korrigiert | K38: #N/A
A39: 30101 | B39: Ecosense_Experiment_Scaffold | C39: TM1_BF_2024_raw | D39: SoilMoisture | E39: m^3/m^3 | F39: Selected Value | G39: =IF(ISBLANK(B39),"-","PT60M") -> PT60M | H39: 5TM | I39: StefanieDumberger_A3_ClaraStock_B1 | J39: =B39&C39&D39 -> Ecosense_Experiment_ScaffoldTM1_BF_2024_rawSoilMoisture | K39: ef87ee512f734b079fe952e41ebfb155
A40: 30102 | B40: Ecosense_Experiment_Scaffold | C40: TM2_BB_2024_raw | D40: SoilMoisture | E40: m^3/m^3 | F40: Selected Value | G40: =IF(ISBLANK(B40),"-","PT60M") -> PT60M | H40: 5TM | I40: StefanieDumberger_A3_ClaraStock_B1 | J40: =B40&C40&D40 -> Ecosense_Experiment_ScaffoldTM2_BB_2024_rawSoilMoisture | K40: d7b7ef8272a44243856dbd7bc6e8e253
A41: 30103 | B41: Ecosense_Experiment_Scaffold | C41: TM4_BB_2024_raw | D41: SoilMoisture | E41: m^3/m^3 | F41: Selected Value | G41: =IF(ISBLANK(B41),"-","PT60M") -> PT60M | H41: 5TM | I41: StefanieDumberger_A3_ClaraStock_B1 | J41: =B41&C41&D41 -> Ecosense_Experiment_ScaffoldTM4_BB_2024_rawSoilMoisture | K41: 573f5bdf73404b65871e596ba8e4f62f
A42: 30104 | B42: Ecosense_Experiment_Scaffold | C42: TM5_DD_2024_raw | D42: SoilMoisture | E42: m^3/m^3 | F42: Selected Value | G42: =IF(ISBLANK(B42),"-","PT60M") -> PT60M | H42: 5TM | I42: StefanieDumberger_A3_ClaraStock_B1 | J42: =B42&C42&D42 -> Ecosense_Experiment_ScaffoldTM5_DD_2024_rawSoilMoisture | K42: 18990c9b077c4a33921b3b026e0aff4e
A43: 30105 | B43: Ecosense_Experiment_Scaffold | C43: TM6_BD_2024_raw | D43: SoilMoisture | E43: m^3/m^3 | F43: Selected Value | G43: =IF(ISBLANK(B43),"-","PT60M") -> PT60M | H43: 5TM | I43: StefanieDumberger_A3_ClaraStock_B1 | J43: =B43&C43&D43 -> Ecosense_Experiment_ScaffoldTM6_BD_2024_rawSoilMoisture | K43: dc73e86336ed4506b7a30e343114c32c
A44: 30106 | B44: Ecosense_Experiment_Scaffold | C44: TM7_DD_2024_raw | D44: SoilMoisture | E44: m^3/m^3 | F44: Selected Value | G44: =IF(ISBLANK(B44),"-","PT60M") -> PT60M | H44: 5TM | I44: StefanieDumberger_A3_ClaraStock_B1 | J44: =B44&C44&D44 -> Ecosense_Experiment_ScaffoldTM7_DD_2024_rawSoilMoisture | K44: 87978ec3b8f84972b5b91e84e1a04eb3
A45: 30107 | B45: Ecosense_Experiment_Scaffold | C45: TM8_BB_2024_raw | D45: SoilMoisture | E45: m^3/m^3 | F45: Selected Value | G45: =IF(ISBLANK(B45),"-","PT60M") -> PT60M | H45: 5TM | I45: StefanieDumberger_A3_ClaraStock_B1 | J45: =B45&C45&D45 -> Ecosense_Experiment_ScaffoldTM8_BB_2024_rawSoilMoisture | K45: 6ec514e7faa94753a90e29b4fe2ec758
A46: 30108 | B46: Ecosense_Experiment_Scaffold | C46: TM9_DD_2024_raw | D46: SoilMoisture | E46: m^3/m^3 | F46: Selected Value | G46: =IF(ISBLANK(B46),"-","PT60M") -> PT60M | H46: 5TM | I46: StefanieDumberger_A3_ClaraStock_B1 | J46: =B46&C46&D46 -> Ecosense_Experiment_ScaffoldTM9_DD_2024_rawSoilMoisture | K46: 110776cbf1524fbd8b067814daca3e99
A47: 30109 | B47: Ecosense_Experiment_Scaffold | C47: TM10_DD_2024_raw | D47: SoilMoisture | E47: m^3/m^3 | F47: Selected Value | G47: =IF(ISBLANK(B47),"-","PT60M") -> PT60M | H47: 5TM | I47: StefanieDumberger_A3_ClaraStock_B1 | J47: =B47&C47&D47 -> Ecosense_Experiment_ScaffoldTM10_DD_2024_rawSoilMoisture | K47: 815b75450eb3413bb5b19f3ec05df8ee
A48: 30110 | B48: Ecosense_Experiment_Scaffold | C48: TM11_BF_2024_raw | D48: SoilMoisture | E48: m^3/m^3 | F48: Selected Value | G48: =IF(ISBLANK(B48),"-","PT60M") -> PT60M | H48: 5TM | I48: StefanieDumberger_A3_ClaraStock_B1 | J48: =B48&C48&D48 -> Ecosense_Experiment_ScaffoldTM11_BF_2024_rawSoilMoisture | K48: 000f84f99fbd428586588c3f25472ce3
A49: 30111 | B49: Ecosense_Experiment_Scaffold | C49: TM12_BF_2024_raw | D49: SoilMoisture | E49: m^3/m^3 | F49: Selected Value | G49: =IF(ISBLANK(B49),"-","PT60M") -> PT60M | H49: 5TM | I49: StefanieDumberger_A3_ClaraStock_B1 | J49: =B49&C49&D49 -> Ecosense_Experiment_ScaffoldTM12_BF_2024_rawSoilMoisture | K49: a183e40a1f0f46718d82ad7f53ff539c
A50: 30112 | B50: Ecosense_Experiment_Scaffold | C50: TM13_BF_2024_raw | D50: SoilMoisture | E50: m^3/m^3 | F50: Selected Value | G50: =IF(ISBLANK(B50),"-","PT60M") -> PT60M | H50: 5TM | I50: StefanieDumberger_A3_ClaraStock_B1 | J50: =B50&C50&D50 -> Ecosense_Experiment_ScaffoldTM13_BF_2024_rawSoilMoisture | K50: 513f28d9781c401ab6241ab7a4626248
... A68: 30130 | B68: Ecosense_Experiment_Scaffold | C68: GS13_BF_2024_raw | D68: SoilMoisture | E68: m^3/m^3 | F68: Selected Value | G68: =IF(ISBLANK(B68),"-","PT60M") -> PT60M | H68: GS1 | I68: StefanieDumberger_A3_ClaraStock_B1 | J68: =B68&C68&D68 -> Ecosense_Experiment_ScaffoldGS13_BF_2024_rawSoilMoisture | K68: d1a45550be3a470e94df7978175982b4
A69: 30131 | B69: Ecosense_Experiment_Scaffold | C69: GS14_BF_2024_raw | D69: SoilMoisture | E69: m^3/m^3 | F69: Selected Value | G69: =IF(ISBLANK(B69),"-","PT60M") -> PT60M | H69: GS1 | I69: StefanieDumberger_A3_ClaraStock_B1 | J69: =B69&C69&D69 -> Ecosense_Experiment_ScaffoldGS14_BF_2024_rawSoilMoisture | K69: 68649108eeb441d299bcccb38f0831bf | L69: 0
A70: 30143 | B70: Ecosense_DouglasFirPlot | C70: DouglasFir_Pure_2_StemWaterPotential | D70: BarPressure | E70: bar | F70: Selected Value | G70: =IF(ISBLANK(B70),"-","PT60M") -> PT60M | H70: FloraPulse_Tensiometer | I70: StefanieDumberger_A3 | J70: =B70&C70&D70 -> Ecosense_DouglasFirPlotDouglasFir_Pure_2_StemWaterPotentialBarPressure | K70: =VLOOKUP(J70,[1]TimeSeriesIDs!$A:$E,5,FALSE) -> 867b583049b6496eba968ade1265297f | L70: 0
A71: 50001 | B71: Ecosense_Soil_Intensive_Plot_1 | C71: Beech_18_depth025cm_dist070cm_W | D71: SoilCO2 | E71: ppm | F71: Selected Value | G71: =IF(ISBLANK(B71),"-","PT60M") -> PT60M | H71: VaisalaCO2Probe | I71: JulianBrzozon_A1 | J71: =B71&C71&D71 -> Ecosense_Soil_Intensive_Plot_1Beech_18_depth025cm_dist070cm_WSoilCO2 | K71: #N/A | L71: 0
A72: 50001 | B72: Ecosense_Soil_Intensive_Plot_1 | C72: Beech_18_depth025cm_dist070cm_W | D72: SoilTemp | E72: degC | F72: Selected Value | G72: =IF(ISBLANK(B72),"-","PT60M") -> PT60M | H72: VaisalaCO2Probe | I72: JulianBrzozon_A1 | J72: =B72&C72&D72 -> Ecosense_Soil_Intensive_Plot_1Beech_18_depth025cm_dist070cm_WSoilTemp | K72: #N/A | L72: 0
A73: 50003 | B73: Ecosense_Soil_Intensive_Plot_1 | C73: Beech_18_depth025cm_dist120cm_W | D73: SoilCO2 | E73: ppm | F73: Selected Value | G73: =IF(ISBLANK(B73),"-","PT60M") -> PT60M | H73: VaisalaCO2Probe | I73: JulianBrzozon_A1 | J73: =B73&C73&D73 -> Ecosense_Soil_Intensive_Plot_1Beech_18_depth025cm_dist120cm_WSoilCO2 | K73: #N/A | L73: 0
A74: 50003 | B74: Ecosense_Soil_Intensive_Plot_1 | C74: Beech_18_depth025cm_dist120cm_W | D74: SoilTemp | E74: degC | F74: Selected Value | G74: =IF(ISBLANK(B74),"-","PT60M") -> PT60M | H74: VaisalaCO2Probe | I74: JulianBrzozon_A1 | J74: =B74&C74&D74 -> Ecosense_Soil_Intensive_Plot_1Beech_18_depth025cm_dist120cm_WSoilTemp | K74: #N/A | L74: 0
A75: 50005 | B75: Ecosense_Soil_Intensive_Plot_1 | C75: Beech_18_depth025cm_dist175cm_W | D75: SoilCO2 | E75: ppm | F75: Selected Value | G75: PT60M | H75: VaisalaCO2Probe | I75: JulianBrzozon_A1 | J75: Ecosense_Soil_Intensive_Plot_1Beech_18_depth025cm_dist175cm_WSoilCO2 | K75: #N/A | L75: 0
A76: 50005 | B76: Ecosense_Soil_Intensive_Plot_1 | C76: Beech_18_depth025cm_dist175cm_W | D76: SoilTemp | E76: degC | F76: Selected Value | G76: PT60M | H76: VaisalaCO2Probe | I76: JulianBrzozon_A1 | J76: Ecosense_Soil_Intensive_Plot_1Beech_18_depth025cm_dist175cm_WSoilTemp | K76: #N/A | L76: 0
A77: 50020 | B77: Ecosense_Soil_Intensive_Plot_1 | C77: Beech_18_depth010cm_dist135cm_W | D77: SoilMoisture_Volt | E77: V | F77: Selected Value | G77: =IF(ISBLANK(B77),"-","PT60M") -> PT60M | H77: DeltaTML2eProbe | I77: JulianBrzozon_A1 | J77: =B77&C77&D77 -> Ecosense_Soil_Intensive_Plot_1Beech_18_depth010cm_dist135cm_WSoilMoisture_Volt | K77: #N/A | L77: 0
A78: 50023 | B78: Ecosense_Soil_Intensive_Plot_1 | C78: Beech_18_depth025cm_dist070cm_W | D78: SoilCO2 | E78: ppm | F78: Selected Value | G78: PT60M | H78: VaisalaCO2Probe | I78: JulianBrzozon_A1 | J78: Ecosense_Soil_Intensive_Plot_1Beech_18_depth025cm_dist070cm_WSoilCO2 | K78: #N/A | L78: 0
A79: 50023 | B79: Ecosense_Soil_Intensive_Plot_1 | C79: Beech_18_depth025cm_dist070cm_W | D79: SoilTemp | E79: degC | F79: Selected Value | G79: PT60M | H79: VaisalaCO2Probe | I79: JulianBrzozon_A1 | J79: Ecosense_Soil_Intensive_Plot_1Beech_18_depth025cm_dist070cm_WSoilTemp | K79: #N/A | L79: 0
...

Sheet  -->

Sheet SensorIDs
B2: Sensor IDs
B3: Each permanent sensor (installed for at least 4 consecutive weeks) gets a unique ID assigned which shall also be deposited within logger files/sensor for a clear attribution of data.
B4: Please note that Logger also get an ID assigned as they send status alerts and battery information.
B10: Sensor IDs
B11: from … | C11: to … | D11: Chair/Research Area/…
B12: 10000 | C12: 29999 | D12: Meteorology
B13: 30000 | C13: 49999 | D13: Ecosystem Physiology
B14: 50000 | C14: 59999 | D14: Soil Ecology
B15: 60000 | C15: 69999 | D15: Hydrology
B17: 70000 | C17: 99999 | D17: Others (contact me if chair is not listed yet)

Sheet Parameter
B2: Parameter Selection
B3: please get in touch if your parameter is not listed
B5: ParameterIdentifier | C5: Description | D5: Unit (default)
B6: AirTemp | C6: Air Temperature | D6: degC
B7: Albedo | C7: Albedo / Reflectivity | D7: %
B8: AtmosphericCO2 | C8: AtmosphericCO2 | D8: ppm
B9: AtmosPres | C9: Atmospheric Pressure | D9: kPa
B10: Attenuationturbidity | C10: Attenuation turbidity, water, unfiltered, broad band light source (400-680 nm), detection angle 180 degrees to incident light, attenuation units (AU) | D10: _ATU
B11: Backscatterturbidity | C11: Backscatter turbidity, water, unfiltered, broad band light source (400-680 nm), detection angle 0-45 degrees to incident light, backscatter units (BU) | D11: _BU
B12: BarPressure | C12: Barometric Pressure (created by SJ) | D12: hPa
B13: BatteryVoltage | C13: Battery Voltage | D13: V
B14: BGAPC | C14: Blue-Green Algae (Phytocyanin) | D14: RFU
B15: C13 | C15: Carbon 13 (created by SJ) | D15: ‰
B16: C13_leaf_continuous | C16: Carbon 13 of leaf, continuous measurement | D16: ‰
... B160: WSpdAvg | C160: Wind Speed Average | D160: m/s

Sheet GapTolerance
B2: Gap Tolerance
B17: ISO 8601 | C17: Interval
B18: PT1M | C18: One minute
B19: PT2H30M | C19: Two and a half hours
B20: P3DT4H59M | C20: Three days, four hours and 59 minutes
B22: If you wish to have no gap tolerance you can leave the cell empty. In that case the timeline will then be interrupted after one missed measurement.

Sheet MeasurementTypes
B2: Type of measurement
B3: A Computation Type refers to a type of calculation that is used to process time-series data. Please contact me if your measurement type is missing.
B5: PublicIdentifier | C5: FormalName | D5: Description
B7: Unknown | C7: None | D7: Please use if measurement type is unknown but try to avoid this option.
B8: Min | C8: Arithmetic Minimum | D8: The Minimum statistic selects the data point with lowest value from the data points with known values in the periodic interval.
B9: Max | C9: Arithmetic Maximum | D9: The Maximum statistic selects the data point with the highest value from the data points with known values in the periodic interval.
B10: Sum | C10: Sum | D10: The Sum statistic computes the value of the aggregate data point as the sum of values of all data points with known values in the periodic interval, including the data points at the boundary of the interval.
B11: Mean | C11: Time Weighted Mean | D11: The Time-Weighted Mean statistic calculates the value of the aggregate data point as the average of all time-weighted data points with known values in the periodic interval.
B12: Median | C12: Arithmetic Median | D12: The Median statistic computes the value of the aggregate data point as the arithmetic median of all data points with known values in the periodic interval.
B13: Selected Value | C13: Selected Value at a Given Time | D13: The Selected Value statistic computes the value of the aggregate data point as the value at a specified time offset within the interval.
B14: Tidal High | C14: Higher High-Tide Values | D14: A point is considered an extreme tide if it is either larger or smaller than all other points within a 2.5 hour range in the periodic interval, excluding points within 2.5 hours of an end of a time-series. The Tidal High statistic is the highest of the extreme high tide values in a periodic interval.
B15: Tidal Lower High | C15: Lower High-Tide Values | D15: A point is considered an extreme tide if it is either larger or smaller than all other points within a 2.5 hour range in the periodic interval, excluding points within 2.5 hours of an end of a time-series. The Tidal Lower High statistic is the lowest of the extreme high tide values in a periodic interval.
B16: Tidal Higher Low | C16: Higher Low-Tide Values | D16: A point is considered an extreme tide if it is either larger or smaller than all other points within a 2.5 hour range in the periodic interval, excluding points within 2.5 hours of an end of a time-series. The Tidal Higher Low statistic is the highest of the extreme low tide values in a periodic interval.
B17: Tidal Low | C17: Lower Low-Tide Values | D17: A point is considered an extreme tide if it is either larger or smaller than all other points within a 2.5 hour range in the periodic interval, excluding points within 2.5 hours of an end of a time-series. The Tidal Low statistic is the lowest of the extreme low tide values in a periodic interval.
... B19: Max At Event Time | C19: Maximum Value at Event Time | D19: The Max at Event Time statistic selects the data point with the highest value from the data points with known values in the periodic interval. The output point is placed at the time of the highest point in the input interval.

Sheet Tabelle4
A3: Zeilenbeschriftungen | B3: Anzahl von Parameter
A4: Temperature | B4: 736
A5: LightSpectrum | B5: 520
A6: SoilTemp | B6: 514
A7: Permittivity | B7: 486
A8: SoilMoisture | B8: 486
A9: Duration | B9: 280
A10: Count | B10: 264
A11: HeatVelocity | B11: 132
A12: LeafTemp | B12: 76
A13: Diagnosticcode | B13: 65
A14: StemRadialVar_Volt | B14: 62
A15: RelHumidity | B15: 62
... A96: Gesamtergebnis | B96: 4418

Sheet sapflow
A5: 60481 | B5: Ecosense_DouglasFirPlot | C5: DouglasFir_Pure_10_+130cm_S | D5: Sapflow | F5: Selected Value | G5: =IF(ISBLANK(B5),"-","PT60M") -> PT60M | I5: LeaDedden_A2_StefanieDumberger_A3
A6: 60482 | B6: Ecosense_DouglasFirPlot | C6: DouglasFir_Pure_9_+130cm_S | D6: Sapflow | F6: Selected Value | G6: =IF(ISBLANK(B6),"-","PT60M") -> PT60M | I6: LeaDedden_A2_StefanieDumberger_A3
A7: 60483 | B7: Ecosense_DouglasFirPlot | C7: DouglasFir_Pure_2_+130cm_S | D7: Sapflow | F7: Selected Value | G7: =IF(ISBLANK(B7),"-","PT60M") -> PT60M | I7: LeaDedden_A2_StefanieDumberger_A3
A8: 60484 | B8: Ecosense_DouglasFirPlot | C8: DouglasFir_Pure_8_+130cm_S | D8: Sapflow | F8: Selected Value | G8: =IF(ISBLANK(B8),"-","PT60M") -> PT60M | I8: LeaDedden_A2_StefanieDumberger_A3
A9: 60485 | B9: Ecosense_DouglasFirPlot | C9: DouglasFir_Pure_7_+130cm_S | D9: Sapflow | F9: Selected Value | G9: =IF(ISBLANK(B9),"-","PT60M") -> PT60M | I9: LeaDedden_A2_StefanieDumberger_A3
A10: 60486 | B10: Ecosense_DouglasFirPlot | C10: DouglasFir_Pure_6_+130cm_S | D10: Sapflow | F10: Selected Value | G10: =IF(ISBLANK(B10),"-","PT60M") -> PT60M | I10: LeaDedden_A2_StefanieDumberger_A3
A11: 60487 | B11: Ecosense_DouglasFirPlot | C11: DouglasFir_Pure_1_+130cm_S | D11: Sapflow | F11: Selected Value | G11: =IF(ISBLANK(B11),"-","PT60M") -> PT60M | I11: LeaDedden_A2_StefanieDumberger_A3
A12: 60488 | B12: Ecosense_DouglasFirPlot | C12: DouglasFir_Pure_5_+130cm_S | D12: Sapflow | F12: Selected Value | G12: =IF(ISBLANK(B12),"-","PT60M") -> PT60M | I12: LeaDedden_A2_StefanieDumberger_A3
A13: 60489 | B13: Ecosense_DouglasFirPlot | C13: DouglasFir_Pure_4_+130cm_S | D13: Sapflow | F13: Selected Value | G13: =IF(ISBLANK(B13),"-","PT60M") -> PT60M | I13: LeaDedden_A2_StefanieDumberger_A3
A14: 60490 | B14: Ecosense_DouglasFirPlot | C14: DouglasFir_Pure_3_+130cm_S | D14: Sapflow | F14: Selected Value | G14: =IF(ISBLANK(B14),"-","PT60M") -> PT60M | I14: LeaDedden_A2_StefanieDumberger_A3
A15: 60491 | B15: Ecosense_BeechPlot | C15: Beech_Pure_3_+130cm_S | D15: Sapflow | F15: Selected Value | G15: =IF(ISBLANK(B15),"-","PT60M") -> PT60M | I15: LeaDedden_A2_StefanieDumberger_A3
A16: 60492 | B16: Ecosense_BeechPlot | C16: Beech_Pure_11_+130cm_S | D16: Sapflow | F16: Selected Value | G16: =IF(ISBLANK(B16),"-","PT60M") -> PT60M | I16: LeaDedden_A2_StefanieDumberger_A3
... A57: 60534 | B57: Ecosense_SilverFirPlot | C57: SilverFir_Pure_7_+130cm_S | D57: Sapflow | F57: Selected Value | G57: =IF(ISBLANK(B57),"-","PT60M") -> PT60M | I57: LeaDedden_A2_StefanieDumberger_A3
